Workbook

Sheet Условия и предпослыки
A1: Стоимость оценки Авто.ру млрд. | B1: 35
A2: Cтоимость оценки Авто.ру Price/Ebitda | B2: 10
A3: Синергетический эффект в операционном доходе (Горизонт - 3 года) млрд. | B3: 45
A4: Рентабельность по EBITDA | B4: 0.35
A6: Вопросы Совета Директоров Яндекса:
A8: - Справедливая стоимость Авто.ру
A9: Комментарий: даем оценку справедливой стоимости + объясняем релевантность методов именно для оценки Авто.ру + описываем саму методологию + считаем оценку в случае пересмотра бизнес - плана в негативную сторону + даем расчет оценки стоимости и ключевые показатели, которые могут быть пересмотрены в отрицательную стоимость покупателем + делаем вывод о том, следует ли часть синергетическог эффекта от слияния Авто.ру и Т учитывать в цене сделки?
A13: - Потенциальные покупатели Авто.ру
A14: Комменатрий: какую цену готовы были бы заплатить другие покупатели и какая доходность их инвестиций ?
A15: - Является ли текущая ситуация подходящей для продажи бизнеса
A16: Комменатрий: какие конкурентные преимущества ииеет Авто.ру на рынке?
A17: - Должен ли Яндекс принять предложение о продаже
A18: - Стоит ли рассматривать продажу другому инвестору, возможно, миноритарного или контрольного пакета
A19: - Следует ли отражать часть ожидаемой синергетической стоимости в цене сделки?
A20: - Если Яндекс не продает актив, то может ли он использовать другие стратегические инициативы (IPO, самостоятельное развитие)

Sheet Модель CF (Менеджмент)
A1: млрд. руб. | C1: 2025Ф | D1: 2026П | E1: 2027П | F1: 2028П | G1: 2029П | H1: 2030П | I1: 2031П | J1: 2032П | K1: 2033П | L1: 2034П | M1: 2035П
A3: Revenue | C3: 10 | D3: 11.5 | E3: 15 | F3: 18.7 | G3: 22.4 | H3: 25.8 | I3: 28.4 | J3: 30.9 | K3: 33.4 | L3: 35.7 | M3: 37.9
B4: % growth y/y | D4: =(D3-C3)/C3 -> 0.15 | E4: =(E3-D3)/D3 -> 0.30434783 | F4: =(F3-E3)/E3 -> 0.24666667 | G4: =(G3-F3)/F3 -> 0.19786096 | H4: =(H3-G3)/G3 -> 0.15178571 | I4: =(I3-H3)/H3 -> 0.10077519 | J4: =(J3-I3)/I3 -> 0.088028169 | K4: =(K3-J3)/J3 -> 0.080906149 | ... M4: =(M3-L3)/L3 -> 0.06162465
A5: EBITDA | C5: 3.5 | D5: 4.3 | E5: 6 | F5: 8 | G5: 10.3 | H5: 12.9 | I5: 14.2 | J5: 15.5 | K5: 16.7 | L5: 17.9 | M5: 18.9
B6: % revenue | C6: =C5/C3 -> 0.35 | D6: =D5/D3 -> 0.37391304 | E6: =E5/E3 -> 0.4 | F6: =F5/F3 -> 0.42780749 | G6: =G5/G3 -> 0.45982143 | H6: =H5/H3 -> 0.5 | I6: =I5/I3 -> 0.5 | J6: =J5/J3 -> 0.50161812 | ... M6: =M5/M3 -> 0.49868074
A7: D&A | C7: 0.1 | D7: 0.1 | E7: 0.1 | F7: 0.2 | G7: 0.2 | H7: 0.3 | I7: 0.3 | J7: 0.3 | K7: 0.3 | L7: 0.4 | M7: 0.4
B8: % revenue | C8: =C7/C3 -> 0.01 | D8: =D7/D3 -> 0.0086956522 | E8: =E7/E3 -> 0.0066666667 | F8: =F7/F3 -> 0.010695187 | G8: =G7/G3 -> 0.0089285714 | H8: =H7/H3 -> 0.011627907 | I8: =I7/I3 -> 0.01056338 | J8: =J7/J3 -> 0.0097087379 | ... M8: =M7/M3 -> 0.01055409
A9: NOPAT | C9: 2.6 | D9: 3.1 | E9: 4.4 | F9: 5.9 | G9: 7.6 | H9: 9.5 | I9: 10.4 | J9: 11.4 | K9: 12.3 | L9: 13.1 | M9: 13.9
A10: Tax Rate | C10: 0.25 | D10: 0.25 | E10: 0.25 | F10: 0.25 | G10: 0.25 | H10: 0.25 | I10: 0.25 | J10: 0.25 | K10: 0.25 | L10: 0.25 | M10: 0.25
A11: CAPEX | C11: 0.2 | D11: 0.2 | E11: 0.3 | F11: 0.4 | G11: 0.4 | H11: 0.5 | I11: 0.5 | J11: 0.5 | K11: 0.5 | L11: 0.4 | M11: 0.4
B12: % revenue | C12: =C11/C3 -> 0.02 | D12: =D11/D3 -> 0.017391304 | E12: =E11/E3 -> 0.02 | F12: =F11/F3 -> 0.021390374 | G12: =G11/G3 -> 0.017857143 | H12: =H11/H3 -> 0.019379845 | I12: =I11/I3 -> 0.017605634 | J12: =J11/J3 -> 0.01618123 | ... M12: =M11/M3 -> 0.01055409
A13: Changing in working capital | C13: 0.2 | D13: 0.2 | E13: 0.3 | F13: 0.4 | G13: 0.4 | H13: 0.5 | I13: 0.6 | J13: 0.6 | K13: 0.7 | L13: 0.7 | M13: 0.8
B14: % revenue | C14: =C13/C3 -> 0.02 | D14: =D13/D3 -> 0.017391304 | E14: =E13/E3 -> 0.02 | F14: =F13/F3 -> 0.021390374 | G14: =G13/G3 -> 0.017857143 | H14: =H13/H3 -> 0.019379845 | I14: =I13/I3 -> 0.021126761 | J14: =J13/J3 -> 0.019417476 | ... M14: =M13/M3 -> 0.021108179

Sheet Модель EV (Саня)
A1: Период | C1: 2026 | D1: 2027 | E1: 2028 | F1: 2029 | G1: 2030 | H1: 2031 | I1: 2032 | J1: 2033 | K1: 2034 | L1: 2035
C2: 1 | D2: 2 | E2: 3 | F2: 4 | G2: 5 | H2: 6 | I2: 7 | J2: 8 | K2: 9 | L2: 10 | N2: (1 - t) | P2: Cost of Equity
A3: EBIT | C3: ='Модель CF (Менеджмент)'!C9/$N3 -> 3.4666667 | D3: ='Модель CF (Менеджмент)'!D9/$N3 -> 4.1333333 | E3: ='Модель CF (Менеджмент)'!E9/$N3 -> 5.8666667 | F3: ='Модель CF (Менеджмент)'!F9/$N3 -> 7.8666667 | G3: ='Модель CF (Менеджмент)'!G9/$N3 -> 10.133333 | H3: ='Модель CF (Менеджмент)'!H9/$N3 -> 12.666667 | I3: ='Модель CF (Менеджмент)'!I9/$N3 -> 13.866667 | J3: ='Модель CF (Менеджмент)'!J9/$N3 -> 15.2 | ... L3: ='Модель CF (Менеджмент)'!L9/$N3 -> 17.466667 | N3: 0.75 | P3: 0.2
A5: FCFF | C5: =(C3 * (0.75) + 'Модель CF (Менеджмент)'!D7 - 'Модель CF (Менеджмент)'!D13 - 'Модель CF (Менеджмент)'!D11) -> 2.3 | D5: =D3 * (0.75) + 'Модель CF (Менеджмент)'!E7 - 'Модель CF (Менеджмент)'!E13 - 'Модель CF (Менеджмент)'!E11 -> 2.6 | E5: =(E3 * (0.75) + 'Модель CF (Менеджмент)'!F7 - 'Модель CF (Менеджмент)'!F13 - 'Модель CF (Менеджмент)'!F11) -> 3.8 | F5: =F3 * (0.75) + 'Модель CF (Менеджмент)'!G7 - 'Модель CF (Менеджмент)'!G13 - 'Модель CF (Менеджмент)'!G11 -> 5.3 | G5: =(G3 * (0.75) + 'Модель CF (Менеджмент)'!H7 - 'Модель CF (Менеджмент)'!H13 - 'Модель CF (Менеджмент)'!H11) -> 6.9 | H5: =H3 * (0.75) + 'Модель CF (Менеджмент)'!I7 - 'Модель CF (Менеджмент)'!I13 - 'Модель CF (Менеджмент)'!I11 -> 8.7 | I5: =(I3 * (0.75) + 'Модель CF (Менеджмент)'!J7 - 'Модель CF (Менеджмент)'!J13 - 'Модель CF (Менеджмент)'!J11) -> 9.6 | J5: =J3 * (0.75) + 'Модель CF (Менеджмент)'!K7 - 'Модель CF (Менеджмент)'!K13 - 'Модель CF (Менеджмент)'!K11 -> 10.5 | K5: =(K3 * (0.75) + 'Модель CF (Менеджмент)'!L7 - 'Модель CF (Менеджмент)'!L13 - 'Модель CF (Менеджмент)'!L11) -> 11.6 | L5: =L3 * (0.75) + 'Модель CF (Менеджмент)'!M7 - 'Модель CF (Менеджмент)'!M13 - 'Модель CF (Менеджмент)'!M11 -> 12.3
N6: Long-Term Growth
A7: DCF | C7: =C5/(1+$P3)^C2 -> 1.9166667 | D7: =D5/(1+$P3)^D2 -> 1.8055556 | E7: =E5/(1+$P3)^E2 -> 2.1990741 | F7: =F5/(1+$P3)^F2 -> 2.5559414 | G7: =G5/(1+$P3)^G2 -> 2.7729552 | H7: =H5/(1+$P3)^H2 -> 2.9136124 | I7: =I5/(1+$P3)^I2 -> 2.6791838 | J7: =J5/(1+$P3)^J2 -> 2.4419644 | ... L7: =L5/(1+$P3)^L2 -> 1.9865187 | N7: 0.04
A9: Cumulative DCF (9 y) | B9: =SUM(C7:K7) -> 21.533111
A11: Terminal Value (DCF) | C11: =(1 / (1 + P3) ^ 9) * L5/(P3 - N7) -> 14.89889 | E11: Value of Buisness (DCF) | F11: =C11 + B9 -> 36.432001
A13: Terminal Value (P/E) | C13: =(1/(1+P3)^9) * 6 * L3 -> 20.310942 | E13: Value of Buisness (P/E) | F13: =B9+C13 -> 41.844053
A17: Samples
A18: Name | B18: Stock Exchange | C18: P/E | D18: Hisrorical P/E
A19: Car Group Ltd (Australia) | B19: ASX | C19: 22/23
A20: Autohome Inc. (China) | B20: NYSE | C20: 17.2 | D20: 14.9
A21: AutoTrader (GB) | B21: LSE | C21: 26
A23: Terminal Value (P/BV)
A25: Terminal Value Checking (PVGO) | C25: =1/(1+P3)^8 * K3/P3 -> 19.070579 | E25: Value Of Buisness (PVGO) | F25: =SUM(C7:J7) +C25 -> 38.355533

Sheet Модель EV (Денч)
B2: В соответствии с предпосылками выбираем DCF-модель
B4: 1. ИСХОДНЫЕ ДОПУЩЕНИЯ
B5: Показатель | C5: Значение | D5: Комментарий
B6: Выручка базового года | C6: 10 | D6: Выручка за последний год
B7: D&A (амортизация), % от выручки | C7: 0.01 | D7: Бухгалтерский расход, не денежный
B8: Изменение NWC, % от выручки | C8: 0.02
B9: Налог на прибыль, % | C9: 0.25
B10: ставка дисконтирования, % | C10: 0.2
B11: Терминальный рост (g), % | C11: 0.04 | D11: Долгосрочный темп роста
B12: EBITDA margin базового года, % | C12: 0.35
B14: Темп роста выручки по годам
B15: Год | C15: 2026 | D15: 2027 | E15: 2028 | F15: 2029 | G15: 2030 | H15: 2031 | I15: 2032 | J15: 2033 | K15: 2034 | L15: 2035
B16: Рост выручки, % | C16: 0.15 | D16: 0.3 | E16: 0.25 | F16: 0.2 | G16: 0.15 | H16: 0.1 | I16: 0.09 | J16: 0.08 | K16: 0.07 | L16: 0.06
B17: EBITDA margin | C17: 0.37 | D17: 0.4 | E17: 0.43 | F17: 0.46 | G17: 0.5 | H17: 0.5 | I17: 0.5 | J17: 0.5 | K17: 0.5 | L17: 0.5
B18: CapEx, % от выручки | C18: 0.02 | D18: 0.02 | E18: 0.02 | F18: 0.02 | G18: 0.02 | H18: 0.018 | I18: 0.016 | J18: 0.014 | K18: 0.012 | L18: 0.01
B19: NOPAT | C19: 3.1 | D19: 4.4 | E19: 5.9 | F19: 7.6 | G19: 9.5 | H19: 10.4 | I19: 11.4 | J19: 12.3 | K19: 13.1 | L19: 13.9
B21: 2. ПРОГНОЗ ФИНАНСОВЫХ ПОКАЗАТЕЛЕЙ
B23: ПОКАЗАТЕЛЬ | C23: 2026 | D23: 2027 | E23: 2028 | F23: 2029 | G23: 2030 | H23: 2031 | I23: 2032 | J23: 2033 | K23: 2034 | L23: 2035
B25: Выручка | C25: 11.5 | D25: 15 | E25: 18.7 | F25: 22.4 | G25: 25.8 | H25: 28.4 | I25: 30.9 | J25: 33.4 | K25: 35.7 | L25: 37.9
B26: EBITDA | C26: 4.255 | D26: 6 | E26: 8.041 | F26: 10.304 | G26: 12.9 | H26: 14.2 | I26: 15.45 | J26: 16.7 | K26: 17.85 | L26: 18.95
B27: D&A (амортизация) | C27: -0.12 | D27: -0.15 | E27: -0.19 | F27: -0.22 | G27: -0.26 | H27: -0.28 | I27: -0.31 | J27: -0.33 | K27: -0.36 | L27: -0.38
B28: EBIT | C28: 4.14 | D28: 5.85 | E28: 7.854 | F28: 10.08 | G28: 12.642 | H28: 13.916 | I28: 15.141 | J28: 16.366 | K28: 17.493 | L28: 18.571
B29: Налог (от EBIT) | C29: 1.035 | D29: 1.4625 | E29: 1.9635 | F29: 2.52 | G29: 3.1605 | H29: 3.479 | I29: 3.78525 | J29: 4.0915 | K29: 4.37325 | L29: 4.64275
B30: NOPAT(данные задания) | C30: 3.1 | D30: 4.4 | E30: 5.9 | F30: 7.6 | G30: 9.5 | H30: 10.4 | I30: 11.4 | J30: 12.3 | K30: 13.1 | L30: 13.9 | M30: округленный
B31: NOPAT(расчетный) = EBIT - tax | C31: 3.1 | D31: 4.4 | E31: 5.9 | F31: 7.6 | G31: 9.5 | H31: 10.4 | I31: 11.4 | J31: 12.3 | K31: 13.1 | L31: 13.9 | M31: неокругленный
B33: 3. ОБОРОТНЫЙ КАПИТАЛ И FCFF
B35: ПОКАЗАТЕЛЬ | C35: 2026 | D35: 2027 | E35: 2028 | F35: 2029 | G35: 2030 | H35: 2031 | I35: 2032 | J35: 2033 | K35: 2034 | L35: 2035
B36: NOPAT(данные задания) | C36: 3.1 | D36: 4.4 | E36: 5.9 | F36: 7.6 | G36: 9.5 | H36: 10.4 | I36: 11.4 | J36: 12.3 | K36: 13.1 | L36: 13.9
B37: NOPAT(расчетный) = EBIT - tax | C37: 3.1 | D37: 4.4 | E37: 5.9 | F37: 7.6 | G37: 9.5 | H37: 10.4 | I37: 11.4 | J37: 12.3 | K37: 13.1 | L37: 13.9
B38: (+) D&A | C38: 0.12 | D38: 0.15 | E38: 0.19 | F38: 0.22 | G38: 0.26 | H38: 0.28 | I38: 0.31 | J38: 0.33 | K38: 0.36 | L38: 0.38
B39: (-)CapEX | C39: -0.23 | D39: -0.3 | E39: -0.37 | F39: -0.45 | G39: -0.52 | H39: -0.51 | I39: -0.49 | J39: -0.47 | K39: -0.43 | L39: -0.38
B41: Изменение NWC | C41: 0.23 | D41: 0.3 | E41: 0.37 | F41: 0.45 | G41: 0.52 | H41: 0.57 | I41: 0.62 | J41: 0.67 | K41: 0.71 | L41: 0.76
B42: FCFF (данные задания) | C42: 2.76 | D42: 3.95 | E42: 5.34 | F42: 6.93 | G42: 8.73 | H42: 9.6 | I42: 10.6 | J42: 11.5 | K42: 12.31 | L42: 13.14
B43: FCFF (расчетный) | C43: 2.76 | D43: 3.94 | E43: 5.33 | F43: 6.89 | G43: 8.71 | H43: 9.64 | I43: 10.55 | J43: 11.47 | K43: 12.33 | L43: 13.17
B45: 4. ДИСКОНТИРОВАНИЕ
B47: Номер года(t) с учетом распределения cash в течение года | C47: 0.5 | D47: 1.5 | E47: 2.5 | F47: 3.5 | G47: 4.5 | H47: 5.5 | I47: 6.5 | J47: 7.5 | K47: 8.5 | L47: 9.5
B48: Коэф. Дисконтирования 1/(1+ставка дисконтирования)^t | C48: 0.91 | D48: 0.76 | E48: 0.63 | F48: 0.53 | G48: 0.44 | H48: 0.37 | I48: 0.31 | J48: 0.25 | K48: 0.21 | L48: 0.18
B50: PV(FCFF) (данные задания) | C50: 2.51 | D50: 3 | E50: 3.38 | F50: 3.66 | G50: 3.84 | H50: 3.52 | I50: 3.24 | J50: 2.93 | K50: 2.61 | L50: 2.33
B51: PV(FCFF) (расчетный) | C51: 2.52 | D51: 3 | E51: 3.38 | F51: 3.64 | G51: 3.83 | H51: 3.54 | I51: 3.23 | J51: 2.92 | K51: 2.62 | L51: 2.33
B53: 5. ТЕРМИНАЛЬНАЯ СТОИМОСТЬ И ОЦЕНКА
...

Sheet Модель EV (Вова)
A1: Параметр | B1: Значение
A2: WACC | B2: 0.2
A3: Долгосрочный рост (g) | B3: 0.04
A4: Ставка налога | B4: 0.25
A5: Чистый долг | B5: 0
A6: Дата оценки | B6: 46112
A7: млрд. руб. | B7: 2025Ф | C7: 2026П | D7: 2027П | E7: 2028П | F7: 2029П | G7: 2030П | H7: 2031П | I7: 2032П | J7: 2033П | K7: 2034П | L7: 2035П
A8: Выручка | B8: 10 | C8: 11.5 | D8: 15 | E8: 18.7 | F8: 22.4 | G8: 25.8 | H8: 28.4 | I8: 30.9 | J8: 33.4 | K8: 35.7 | L8: 37.9
A9: % рост г/г | C9: 0.15 | D9: 0.3 | E9: 0.25 | F9: 0.2 | G9: 0.15 | H9: 0.1 | I9: 0.09 | J9: 0.08 | K9: 0.07 | L9: 0.06
A10: EBITDA | B10: 3.5 | C10: 4.3 | D10: 6 | E10: 8 | F10: 10.3 | G10: 12.9 | H10: 14.2 | I10: 15.5 | J10: 16.7 | K10: 17.9 | L10: 18.9
A11: % выручки | B11: 0.35 | C11: 0.37 | D11: 0.4 | E11: 0.43 | F11: 0.46 | G11: 0.5 | H11: 0.5 | I11: 0.5 | J11: 0.5 | K11: 0.5 | L11: 0.5
A12: D&A | B12: 0.1 | C12: 0.1 | D12: 0.1 | E12: 0.2 | F12: 0.2 | G12: 0.3 | H12: 0.3 | I12: 0.3 | J12: 0.3 | K12: 0.4 | L12: 0.4
A13: % выручки | B13: 0.01 | C13: 0.01 | D13: 0.01 | E13: 0.01 | F13: 0.01 | G13: 0.01 | H13: 0.01 | I13: 0.01 | J13: 0.01 | K13: 0.01 | L13: 0.01
A14: NOPAT | B14: 2.6 | C14: 3.1 | D14: 4.4 | E14: 5.9 | F14: 7.6 | G14: 9.5 | H14: 10.4 | I14: 11.4 | J14: 12.3 | K14: 13.1 | L14: 13.9
A15: % ставки налога | B15: 0.25 | C15: 0.25 | D15: 0.25 | E15: 0.25 | F15: 0.25 | G15: 0.25 | H15: 0.25 | I15: 0.25 | J15: 0.25 | K15: 0.25 | L15: 0.25
A16: Капитальные затраты | B16: 0.2 | C16: 0.2 | D16: 0.3 | E16: 0.4 | F16: 0.4 | G16: 0.5 | H16: 0.5 | I16: 0.5 | J16: 0.5 | K16: 0.4 | L16: 0.4
A17: % выручки | B17: 0.02 | C17: 0.02 | D17: 0.02 | E17: 0.02 | F17: 0.02 | G17: 0.02 | H17: 0.02 | I17: 0.02 | J17: 0.01 | K17: 0.01 | L17: 0.01
A18: Уменьшение/(увеличение) оборотного капитала | B18: 0.2 | C18: 0.2 | D18: 0.3 | E18: 0.4 | F18: 0.4 | G18: 0.5 | H18: 0.6 | I18: 0.6 | J18: 0.7 | K18: 0.7 | L18: 0.8
A19: % выручки | B19: 0.02 | C19: 0.02 | D19: 0.02 | E19: 0.02 | F19: 0.02 | G19: 0.02 | H19: 0.02 | I19: 0.02 | J19: 0.02 | K19: 0.02 | L19: 0.02
A21: FCF | C21: =C14+C12-C16-C18 -> 2.8 | D21: =D14+D12-D16-D18 -> 3.9 | E21: =E14+E12-E16-E18 -> 5.3 | F21: =F14+F12-F16-F18 -> 7 | G21: =G14+G12-G16-G18 -> 8.8 | H21: =H14+H12-H16-H18 -> 9.6 | I21: =I14+I12-I16-I18 -> 10.6 | J21: =J14+J12-J16-J18 -> 11.4 | ... L21: =L14+L12-L16-L18 -> 13.1
A23: Год | C23: 1 | D23: =C23+1 -> 2 | E23: =D23+1 -> 3 | F23: =E23+1 -> 4 | G23: =F23+1 -> 5 | H23: =G23+1 -> 6 | I23: =H23+1 -> 7 | J23: =I23+1 -> 8 | K23: =J23+1 -> 9 | L23: =K23+1 -> 10
A24: К дисконтирования | C24: =1/(1+$B$2)^C23 -> 0.83333333 | D24: =1/(1+$B$2)^D23 -> 0.69444444 | E24: =1/(1+$B$2)^E23 -> 0.5787037 | F24: =1/(1+$B$2)^F23 -> 0.48225309 | G24: =1/(1+$B$2)^G23 -> 0.40187757 | H24: =1/(1+$B$2)^H23 -> 0.33489798 | I24: =1/(1+$B$2)^I23 -> 0.27908165 | J24: =1/(1+$B$2)^J23 -> 0.23256804 | ... L24: =1/(1+$B$2)^L23 -> 0.16150558
A25: PV FCF | C25: =C21*C24 -> 2.3333333 | D25: =D21*D24 -> 2.7083333 | E25: =E21*E24 -> 3.0671296 | F25: =F21*F24 -> 3.3757716 | G25: =G21*G24 -> 3.5365226 | H25: =H21*H24 -> 3.2150206 | I25: =I21*I24 -> 2.9582655 | J25: =J21*J24 -> 2.6512756 | ... L25: =L21*L24 -> 2.1157231
A27: Сумм PV FCF | B27: =SUM(C25:L25) -> 28.364578
A28: FCF в последний год (2035) | B28: =L21 -> 13.1
A29: TV | B29: =B28*(1+$B$3)/($B$2-$B$3) -> 85.15
A30: PV TV | B30: =B29/(1+$B$2)^10 -> 13.7522
A31: EV | B31: =B27+B30 -> 42.116779
